<?xml version="1.0"?>
<robot xmlns:xacro="http://ros.org/wiki/xacro" name="crab">

<!-- Pi parameter -->
<!--
<xacro:property name="pi" value="3.1415926535897931" />
-->

<!-- Build the body frame -->
    <link name="base_link">
        <collision>
            <origin xyz="0 0 0" rpy="0 0 0"/>
            <geometry>
                <box size="0 0 0"/>
            </geometry>
        </collision>
        <visual>
            <origin xyz="0 0 0" rpy="0 0 0"/>
            <geometry>
                <box size="0 0 0"/>
            </geometry>
            <material name="grey">
                <color rgba="0.5 0.5 0.5 1" />
            </material>
        </visual>
        <inertial>
            <origin xyz="0 0 0" rpy="0 0 0"/>
            <mass value="0.5"/>
            <inertia
                ixx="0.0001" ixy="0.0" ixz="0.0"
                iyy="0.0001" iyz="0.0"
                izz="0.0001"/>
        </inertial>
    </link>
    <joint name="base_joint" type="fixed">
        <parent link="base_link" />
        <child link="thorax" />
        <origin xyz="0 0 0" rpy="0 0 0" />
    </joint>

    <gazebo reference="base_link">
        <selfCollide>true</selfCollide>
        <material name="orange">
          <color rgba="${255/255} ${108/255} ${10/255} 1.0"/>
        </material>
    </gazebo>

    <link name="thorax">
        <collision>
            <origin xyz="0 0 0" rpy="0 0 0"/>
            <geometry>
                <mesh filename="package://crab_description/meshes/thorax.STL" />
            </geometry>
        </collision>
        <visual>
            <origin	xyz="0 0 0" rpy="0 0 0" />
            <geometry>
                <mesh filename="package://crab_description/meshes/thorax.STL" />
            </geometry>
            <material name="grey">
                <color rgba="0.5 0.5 0.5 1" />
            </material>
        </visual>
        <inertial>
            <origin xyz="0 0 0" rpy="0 0 0"/>
            <mass value="0.02"/>
            <inertia
                ixx="0.0001" ixy="0.0" ixz="0.0"
                iyy="0.0001" iyz="0.0"
                izz="0.0001"/>
        </inertial>
    </link>

<!-- Joint properties -->
    <xacro:property name="joint_lower_limit" value="-${1.5}" />
    <xacro:property name="joint_upper_limit" value="${1.5}" />
    <xacro:property name="joint_effort" value="10000" />
    <xacro:property name="joint_velocity" value="100" />

<!-- Leg macros -->
    <xacro:macro name="leg" params="side num x y angle">

<!-- Build leg -->
    <joint name="leg_center_joint_${side}${num}" type="fixed">
        <origin xyz="${x} ${y} 0" rpy="0 0 0" />
        <parent link="thorax" />
        <child link="leg_center_${side}${num}" />
    </joint>
    <gazebo reference="thorax">
        <selfCollide>true</selfCollide>
        <material>Gazebo/Orange</material>
    </gazebo>

    <link name="leg_center_${side}${num}">
        <collision>
            <origin xyz="0 0 0" rpy="0 0 0"/>
            <geometry>
                <box size="0 0 0"/>
            </geometry>
        </collision>
        <visual>
            <origin xyz="0 0 0" rpy="0 0 0"/>
            <geometry>
                <box size="0 0 0"/>
            </geometry>
            <material name="grey">
                <color rgba="0.5 0.5 0.5 1" />
            </material>
        </visual>
        <inertial>
            <origin xyz="0 0 0" rpy="0 0 0"/>
            <mass value="0.02"/> <!-- The mass has to be recomputed -->
            <inertia
                ixx="0.011935/10000" ixy="0.0" ixz="-0.000021/10000"
                iyy="0.022562/10000" iyz="-0.000001/10000"
                izz="0.026533/10000"/>
        </inertial>
    </link>
    <gazebo reference="leg_center_${side}${num}">
        <selfCollide>true</selfCollide>
        <material>Gazebo/Grey</material>
    </gazebo>

    <joint name="coxa_joint_${side}${num}" type="revolute">
        <origin xyz="0 0 0" rpy="0 0 ${angle}" />
        <parent link="leg_center_${side}${num}" />
        <child link="coxa_${side}${num}" />
        <axis xyz="0 0 -1" />
        <limit lower="${joint_lower_limit}" upper="${joint_upper_limit}" effort="${joint_effort}" velocity="${joint_velocity}" />
    </joint>

    <link name="coxa_${side}${num}">
        <collision>
            <origin xyz="0 0 0" rpy="0 0 0"/>
            <geometry>
                <mesh filename="package://crab_description/meshes/coxa_${side}.STL" />
            </geometry>
        </collision>
        <visual>
            <origin xyz="0 0 0" rpy="0 0 0" />
            <geometry>
                <mesh filename="package://crab_description/meshes/coxa_${side}.STL" />
            </geometry>
            <material name="">
                <color rgba="0.7 0.7 0 1" />
            </material>
        </visual>
        <inertial>
            <origin xyz="0 0 0" rpy="0 0 0"/>
            <mass value="0.02"/>
            <inertia
                ixx="0.0001" ixy="0.0" ixz="0.0"
                iyy="0.0001" iyz="0.0"
                izz="0.0001"/>
        </inertial>
    </link>
    <gazebo reference="coxa_${side}${num}">
        <selfCollide>true</selfCollide>
        <material>Gazebo/Grey</material>
    </gazebo>

    <joint name="femur_joint_${side}${num}" type="revolute">
        <origin xyz="0.0294 0 0" rpy="-${pi/2} 0 0" />
        <parent link="coxa_${side}${num}" />
        <child link="femur_${side}${num}" />
        <axis xyz="0 0 -1" />
        <limit lower="${joint_lower_limit}" upper="${joint_upper_limit}" effort="${joint_effort}" velocity="${joint_velocity}" />
    </joint>

    <link name="femur_${side}${num}">
        <collision>
            <origin xyz="0 0 0" rpy="0 0 0"/>
            <geometry>
                <mesh filename="package://crab_description/meshes/femur_${side}.STL" />
            </geometry>
        </collision>
        <visual>
            <origin xyz="0 0 0" rpy="0 0 0" />
            <geometry>
                <mesh filename="package://crab_description/meshes/femur_${side}.STL" />
            </geometry>
            <material name="">
                <color rgba="0 0.7 0.7 1" />
            </material>
        </visual>
        <inertial>
            <origin xyz="0 0 0" rpy="0 0 0"/>
            <mass value="0.02"/>
            <inertia
                ixx="0.0001" ixy="0.0" ixz="0.0"
                iyy="0.0001" iyz="0.0"
                izz="0.0001"/>
        </inertial>
    </link>
    <gazebo reference="femur_${side}${num}">
        <selfCollide>true</selfCollide>
        <material>Gazebo/Grey</material>
    </gazebo>

    <joint name="tibia_joint_${side}${num}" type="revolute">
        <origin xyz="0.08 0 0" rpy="${pi} 0 ${pi/2}" />
        <parent link="femur_${side}${num}" />
        <child link="tibia_${side}${num}" />
        <axis xyz="0 0 1" />
        <limit lower="${joint_lower_limit}" upper="${joint_upper_limit}" effort="${joint_effort}" velocity="${joint_velocity}" />
    </joint>

    <link name="tibia_${side}${num}">
        <collision>
            <origin xyz="0 0 0" rpy="0 0 0"/>
            <geometry>
                <mesh filename="package://crab_description/meshes/femur_${side}.STL" />
            </geometry>
        </collision>
        <visual>
            <origin xyz="0 0 0" rpy="0 0 0.06" />
            <geometry>
                <mesh filename="package://crab_description/meshes/tibia_${side}.STL" />
            </geometry>
            <material name="">
                <color rgba="0.7 0 0.7 1" />
            </material>
        </visual>
        <inertial>
            <origin xyz="0 0 0" rpy="0 0 0"/>
            <mass value="0.02"/>
            <inertia
                ixx="0.0001" ixy="0.0" ixz="0.0"
                iyy="0.0001" iyz="0.0"
                izz="0.0001"/>
        </inertial>
    </link>
    <gazebo reference="tibia_${side}${num}">
        <selfCollide>true</selfCollide>
        <material>Gazebo/Grey</material>
    </gazebo>

    <joint name="tibia_foot_joint_${side}${num}" type="fixed">
        <origin xyz="0.117 0 0" rpy="0 0 0" />
        <parent link="tibia_${side}${num}" />
        <child link="tibia_foot_${side}${num}" />
    </joint>

    <link name="tibia_foot_${side}${num}" />
    <gazebo reference="tibia_foot_${side}${num}">
        <selfCollide>true</selfCollide>
        <material>Gazebo/Grey</material>
    </gazebo>

</xacro:macro>

<!-- Build robot model -->
    <xacro:leg side="r" num="1" x="0.087598" 	y="-0.050575" 	angle="-${pi/3}" />
    <xacro:leg side="r" num="2" x="0" 		y="-0.06985" 	angle="-${pi/2}" />
    <xacro:leg side="r" num="3" x="-0.087598" 	y="-0.050575" 	angle="-${pi*2/3}" />
    <xacro:leg side="l" num="1" x="0.087598" 	y="0.050575"	angle="${pi/3}" />
    <xacro:leg side="l" num="2" x="0" 		y="0.06985"	angle="${pi/2}" />
    <xacro:leg side="l" num="3" x="-0.087598" 	y="0.050575" 	angle="${pi*2/3}" />

</robot>
